Workbook
Name Slicer_Gender: #N/A
Name Slicer_Generation: #N/A
Name Slicer_Product_Category: #N/A

Sheet retail_sales_dataset
A1: Transaction ID | B1: Year | C1: Month | D1: Day | F1: Day Name | G1: Date | H1: Customer ID | I1: Gender | J1: Age | K1: Generation | L1: Product Category | M1: Quantity | N1: Price per Unit | O1: Total Sales | P1: Commision 2023
A2: 1 | B2: =YEAR(G2) -> 2023 | C2: =MONTH(G2) -> 11 | D2: =DAY(G2) -> 24 | E2: =TEXT(G2, "mmmm") -> November | F2: =TEXT(G2, "dddd") -> Friday | G2: 45254 | H2: CUST001 | I2: Male | J2: 34 | K2: {=_xlfn.IFS(J2<30, "Young Adult", J2<50, "Adult", J2>=50, "Senior")} -> Adult | L2: Beauty | M2: 3 | N2: 50 | O2: =M2*N2 -> 150 | P2: =O2*$S$3 -> 2.25 | S2: Rate %
A3: 2 | B3: =YEAR(G3) -> 2023 | C3: =MONTH(G3) -> 2 | D3: =DAY(G3) -> 27 | E3: =TEXT(G3, "mmmm") -> February | F3: =TEXT(G3, "dddd") -> Monday | G3: 44984 | H3: CUST002 | I3: Female | J3: 26 | K3: {=_xlfn.IFS(J3<30, "Young Adult", J3<50, "Adult", J3>=50, "Senior")} -> Young Adult | L3: Clothing | M3: 2 | N3: 500 | O3: =M3*N3 -> 1000 | P3: =O3*$S$3 -> 15 | R3: commision rate 2023 | S3: 0.015
A4: 3 | B4: =YEAR(G4) -> 2023 | C4: =MONTH(G4) -> 1 | D4: =DAY(G4) -> 13 | E4: =TEXT(G4, "mmmm") -> January | F4: =TEXT(G4, "dddd") -> Friday | G4: 44939 | H4: CUST003 | I4: Male | J4: 50 | K4: {=_xlfn.IFS(J4<30, "Young Adult", J4<50, "Adult", J4>=50, "Senior")} -> Senior | L4: Electronics | M4: 1 | N4: 30 | O4: =M4*N4 -> 30 | P4: =O4*$S$3 -> 0.45 | R4: commision rate 2024 | S4: 0.02
A5: 4 | B5: =YEAR(G5) -> 2023 | C5: =MONTH(G5) -> 5 | D5: =DAY(G5) -> 21 | E5: =TEXT(G5, "mmmm") -> May | F5: =TEXT(G5, "dddd") -> Sunday | G5: 45067 | H5: CUST004 | I5: Male | J5: 37 | K5: {=_xlfn.IFS(J5<30, "Young Adult", J5<50, "Adult", J5>=50, "Senior")} -> Adult | L5: Clothing | M5: 1 | N5: 500 | O5: =M5*N5 -> 500 | P5: =O5*$S$3 -> 7.5
A6: 5 | B6: =YEAR(G6) -> 2023 | C6: =MONTH(G6) -> 5 | D6: =DAY(G6) -> 6 | E6: =TEXT(G6, "mmmm") -> May | F6: =TEXT(G6, "dddd") -> Saturday | G6: 45052 | H6: CUST005 | I6: Male | J6: 30 | K6: {=_xlfn.IFS(J6<30, "Young Adult", J6<50, "Adult", J6>=50, "Senior")} -> Adult | L6: Beauty | M6: 2 | N6: 50 | O6: =M6*N6 -> 100 | P6: =O6*$S$3 -> 1.5
A7: 6 | B7: =YEAR(G7) -> 2023 | C7: =MONTH(G7) -> 4 | D7: =DAY(G7) -> 25 | E7: =TEXT(G7, "mmmm") -> April | F7: =TEXT(G7, "dddd") -> Tuesday | G7: 45041 | H7: CUST006 | I7: Female | J7: 45 | K7: {=_xlfn.IFS(J7<30, "Young Adult", J7<50, "Adult", J7>=50, "Senior")} -> Adult | L7: Beauty | M7: 1 | N7: 30 | O7: =M7*N7 -> 30 | P7: =O7*$S$3 -> 0.45
A8: 7 | B8: =YEAR(G8) -> 2023 | C8: =MONTH(G8) -> 3 | D8: =DAY(G8) -> 13 | E8: =TEXT(G8, "mmmm") -> March | F8: =TEXT(G8, "dddd") -> Monday | G8: 44998 | H8: CUST007 | I8: Male | J8: 46 | K8: {=_xlfn.IFS(J8<30, "Young Adult", J8<50, "Adult", J8>=50, "Senior")} -> Adult | L8: Clothing | M8: 2 | N8: 25 | O8: =M8*N8 -> 50 | P8: =O8*$S$3 -> 0.75 | S8: Total | T8: Male | U8: Female | V8: Average sales
A9: 8 | B9: =YEAR(G9) -> 2023 | C9: =MONTH(G9) -> 2 | D9: =DAY(G9) -> 22 | E9: =TEXT(G9, "mmmm") -> February | F9: =TEXT(G9, "dddd") -> Wednesday | G9: 44979 | H9: CUST008 | I9: Male | J9: 30 | K9: {=_xlfn.IFS(J9<30, "Young Adult", J9<50, "Adult", J9>=50, "Senior")} -> Adult | L9: Electronics | M9: 4 | N9: 25 | O9: =M9*N9 -> 100 | P9: =O9*$S$3 -> 1.5 | R9: all products | S9: =SUM(O:O) -> 456000 | T9: =SUM(T10:T12) -> 1216 | U9: =SUM(U10:U12) -> 1298 | V9: =AVERAGE(O:O) -> 456
A10: 9 | B10: =YEAR(G10) -> 2023 | C10: =MONTH(G10) -> 12 | D10: =DAY(G10) -> 13 | E10: =TEXT(G10, "mmmm") -> December | F10: =TEXT(G10, "dddd") -> Wednesday | G10: 45273 | H10: CUST009 | I10: Male | J10: 63 | K10: {=_xlfn.IFS(J10<30, "Young Adult", J10<50, "Adult", J10>=50, "Senior")} -> Senior | L10: Electronics | M10: 2 | N10: 300 | O10: =M10*N10 -> 600 | P10: =O10*$S$3 -> 9 | R10: Clothing | S10: =SUMIF(L:L, "clothing", O:O) -> 155580 | T10: =SUMIFS(M:M, L:L, "Clothing", I:I, "Male") -> 453 | U10: =SUMIFS(M:M, L:L, "Clothing", I:I, "Female") -> 441 | V10: =AVERAGEIF($L:$L, R10, $O:$O) -> 443.24786
A11: 10 | B11: =YEAR(G11) -> 2023 | C11: =MONTH(G11) -> 10 | D11: =DAY(G11) -> 7 | E11: =TEXT(G11, "mmmm") -> October | F11: =TEXT(G11, "dddd") -> Saturday | G11: 45206 | H11: CUST010 | I11: Female | J11: 52 | K11: {=_xlfn.IFS(J11<30, "Young Adult", J11<50, "Adult", J11>=50, "Senior")} -> Senior | L11: Clothing | M11: 4 | N11: 50 | O11: =M11*N11 -> 200 | P11: =O11*$S$3 -> 3 | R11: Beauty | S11: =SUMIF(L:L, "Beauty", O:O) -> 143515 | T11: =SUMIFS(M:M, L:L, "Beauty", I:I, "Male") -> 353 | U11: =SUMIFS(M:M, L:L, "Beauty", I:I, "Female") -> 418 | V11: =AVERAGEIF($L:$L, R11, $O:$O) -> 467.47557
A12: 11 | B12: =YEAR(G12) -> 2023 | C12: =MONTH(G12) -> 2 | D12: =DAY(G12) -> 14 | E12: =TEXT(G12, "mmmm") -> February | F12: =TEXT(G12, "dddd") -> Tuesday | G12: 44971 | H12: CUST011 | I12: Male | J12: 23 | K12: {=_xlfn.IFS(J12<30, "Young Adult", J12<50, "Adult", J12>=50, "Senior")} -> Young Adult | L12: Clothing | M12: 2 | N12: 50 | O12: =M12*N12 -> 100 | P12: =O12*$S$3 -> 1.5 | R12: Electronics | S12: =SUMIF(L:L, "Electronics", O:O) -> 156905 | T12: =SUMIFS(M:M, L:L, "electronics", I:I, "Male") -> 410 | U12: =SUMIFS(M:M, L:L, "electronics", I:I, "Female") -> 439 | V12: =AVERAGEIF($L:$L, R12, $O:$O) -> 458.78655
A13: 12 | B13: =YEAR(G13) -> 2023 | C13: =MONTH(G13) -> 10 | D13: =DAY(G13) -> 30 | E13: =TEXT(G13, "mmmm") -> October | F13: =TEXT(G13, "dddd") -> Monday | G13: 45229 | H13: CUST012 | I13: Male | J13: 35 | K13: {=_xlfn.IFS(J13<30, "Young Adult", J13<50, "Adult", J13>=50, "Senior")} -> Adult | L13: Beauty | M13: 3 | N13: 25 | O13: =M13*N13 -> 75 | P13: =O13*$S$3 -> 1.125
A14: 13 | B14: =YEAR(G14) -> 2023 | C14: =MONTH(G14) -> 8 | D14: =DAY(G14) -> 5 | E14: =TEXT(G14, "mmmm") -> August | F14: =TEXT(G14, "dddd") -> Saturday | G14: 45143 | H14: CUST013 | I14: Male | J14: 22 | K14: {=_xlfn.IFS(J14<30, "Young Adult", J14<50, "Adult", J14>=50, "Senior")} -> Young Adult | L14: Electronics | M14: 3 | N14: 500 | O14: =M14*N14 -> 1500 | P14: =O14*$S$3 -> 22.5 | R14: {=_xlfn.UNIQUE(L2:L1001)} -> Beauty
A15: 14 | B15: =YEAR(G15) -> 2023 | C15: =MONTH(G15) -> 1 | D15: =DAY(G15) -> 17 | E15: =TEXT(G15, "mmmm") -> January | F15: =TEXT(G15, "dddd") -> Tuesday | G15: 44943 | H15: CUST014 | I15: Male | J15: 64 | K15: {=_xlfn.IFS(J15<30, "Young Adult", J15<50, "Adult", J15>=50, "Senior")} -> Senior | L15: Clothing | M15: 4 | N15: 30 | O15: =M15*N15 -> 120 | P15: =O15*$S$3 -> 1.8 | R15: Clothing
A16: 15 | B16: =YEAR(G16) -> 2023 | C16: =MONTH(G16) -> 1 | D16: =DAY(G16) -> 16 | E16: =TEXT(G16, "mmmm") -> January | F16: =TEXT(G16, "dddd") -> Monday | G16: 44942 | H16: CUST015 | I16: Female | J16: 42 | K16: {=_xlfn.IFS(J16<30, "Young Adult", J16<50, "Adult", J16>=50, "Senior")} -> Adult | L16: Electronics | M16: 4 | N16: 500 | O16: =M16*N16 -> 2000 | P16: =O16*$S$3 -> 30 | R16: Electronics
A17: 16 | B17: =YEAR(G17) -> 2023 | C17: =MONTH(G17) -> 2 | D17: =DAY(G17) -> 17 | E17: =TEXT(G17, "mmmm") -> February | F17: =TEXT(G17, "dddd") -> Friday | G17: 44974 | H17: CUST016 | I17: Male | J17: 19 | K17: {=_xlfn.IFS(J17<30, "Young Adult", J17<50, "Adult", J17>=50, "Senior")} -> Young Adult | L17: Clothing | M17: 3 | N17: 500 | O17: =M17*N17 -> 1500 | P17: =O17*$S$3 -> 22.5
A18: 17 | B18: =YEAR(G18) -> 2023 | C18: =MONTH(G18) -> 4 | D18: =DAY(G18) -> 22 | E18: =TEXT(G18, "mmmm") -> April | F18: =TEXT(G18, "dddd") -> Saturday | G18: 45038 | H18: CUST017 | I18: Female | J18: 27 | K18: {=_xlfn.IFS(J18<30, "Young Adult", J18<50, "Adult", J18>=50, "Senior")} -> Young Adult | L18: Clothing | M18: 4 | N18: 25 | O18: =M18*N18 -> 100 | P18: =O18*$S$3 -> 1.5 | R18: Commision Total | S18: =SUM(P:P) -> 6840
A19: 18 | B19: =YEAR(G19) -> 2023 | C19: =MONTH(G19) -> 4 | D19: =DAY(G19) -> 30 | E19: =TEXT(G19, "mmmm") -> April | F19: =TEXT(G19, "dddd") -> Sunday | G19: 45046 | H19: CUST018 | I19: Female | J19: 47 | K19: {=_xlfn.IFS(J19<30, "Young Adult", J19<50, "Adult", J19>=50, "Senior")} -> Adult | L19: Electronics | M19: 2 | N19: 25 | O19: =M19*N19 -> 50 | P19: =O19*$S$3 -> 0.75 | R19: Commision Average | S19: =AVERAGE(P:P) -> 6.84
A20: 19 | B20: =YEAR(G20) -> 2023 | C20: =MONTH(G20) -> 9 | D20: =DAY(G20) -> 16 | E20: =TEXT(G20, "mmmm") -> September | F20: =TEXT(G20, "dddd") -> Saturday | G20: 45185 | H20: CUST019 | I20: Female | J20: 62 | K20: {=_xlfn.IFS(J20<30, "Young Adult", J20<50, "Adult", J20>=50, "Senior")} -> Senior | L20: Clothing | M20: 2 | N20: 25 | O20: =M20*N20 -> 50 | P20: =O20*$S$3 -> 0.75
A21: 20 | B21: =YEAR(G21) -> 2023 | C21: =MONTH(G21) -> 11 | D21: =DAY(G21) -> 5 | E21: =TEXT(G21, "mmmm") -> November | F21: =TEXT(G21, "dddd") -> Sunday | G21: 45235 | H21: CUST020 | I21: Male | J21: 22 | K21: {=_xlfn.IFS(J21<30, "Young Adult", J21<50, "Adult", J21>=50, "Senior")} -> Young Adult | L21: Clothing | M21: 3 | N21: 300 | O21: =M21*N21 -> 900 | P21: =O21*$S$3 -> 13.5
A22: 21 | B22: =YEAR(G22) -> 2023 | C22: =MONTH(G22) -> 1 | D22: =DAY(G22) -> 14 | E22: =TEXT(G22, "mmmm") -> January | F22: =TEXT(G22, "dddd") -> Saturday | G22: 44940 | H22: CUST021 | I22: Female | J22: 50 | K22: {=_xlfn.IFS(J22<30, "Young Adult", J22<50, "Adult", J22>=50, "Senior")} -> Senior | L22: Beauty | M22: 1 | N22: 500 | O22: =M22*N22 -> 500 | P22: =O22*$S$3 -> 7.5
A23: 22 | B23: =YEAR(G23) -> 2023 | C23: =MONTH(G23) -> 10 | D23: =DAY(G23) -> 15 | E23: =TEXT(G23, "mmmm") -> October | F23: =TEXT(G23, "dddd") -> Sunday | G23: 45214 | H23: CUST022 | I23: Male | J23: 18 | K23: {=_xlfn.IFS(J23<30, "Young Adult", J23<50, "Adult", J23>=50, "Senior")} -> Young Adult | L23: Clothing | M23: 2 | N23: 50 | O23: =M23*N23 -> 100 | P23: =O23*$S$3 -> 1.5
A24: 23 | B24: =YEAR(G24) -> 2023 | C24: =MONTH(G24) -> 4 | D24: =DAY(G24) -> 12 | E24: =TEXT(G24, "mmmm") -> April | F24: =TEXT(G24, "dddd") -> Wednesday | G24: 45028 | H24: CUST023 | I24: Female | J24: 35 | K24: {=_xlfn.IFS(J24<30, "Young Adult", J24<50, "Adult", J24>=50, "Senior")} -> Adult | L24: Clothing | M24: 4 | N24: 30 | O24: =M24*N24 -> 120 | P24: =O24*$S$3 -> 1.8
A25: 24 | B25: =YEAR(G25) -> 2023 | C25: =MONTH(G25) -> 11 | D25: =DAY(G25) -> 29 | E25: =TEXT(G25, "mmmm") -> November | F25: =TEXT(G25, "dddd") -> Wednesday | G25: 45259 | H25: CUST024 | I25: Female | J25: 49 | K25: {=_xlfn.IFS(J25<30, "Young Adult", J25<50, "Adult", J25>=50, "Senior")} -> Adult | L25: Clothing | M25: 1 | N25: 300 | O25: =M25*N25 -> 300 | P25: =O25*$S$3 -> 4.5
A26: 25 | B26: =YEAR(G26) -> 2023 | C26: =MONTH(G26) -> 12 | D26: =DAY(G26) -> 26 | E26: =TEXT(G26, "mmmm") -> December | F26: =TEXT(G26, "dddd") -> Tuesday | G26: 45286 | H26: CUST025 | I26: Female | J26: 64 | K26: {=_xlfn.IFS(J26<30, "Young Adult", J26<50, "Adult", J26>=50, "Senior")} -> Senior | L26: Beauty | M26: 1 | N26: 50 | O26: =M26*N26 -> 50 | P26: =O26*$S$3 -> 0.75
A27: 26 | B27: =YEAR(G27) -> 2023 | C27: =MONTH(G27) -> 10 | D27: =DAY(G27) -> 7 | E27: =TEXT(G27, "mmmm") -> October | F27: =TEXT(G27, "dddd") -> Saturday | G27: 45206 | H27: CUST026 | I27: Female | J27: 28 | K27: {=_xlfn.IFS(J27<30, "Young Adult", J27<50, "Adult", J27>=50, "Senior")} -> Young Adult | L27: Electronics | M27: 2 | N27: 500 | O27: =M27*N27 -> 1000 | P27: =O27*$S$3 -> 15
A28: 27 | B28: =YEAR(G28) -> 2023 | C28: =MONTH(G28) -> 8 | D28: =DAY(G28) -> 3 | E28: =TEXT(G28, "mmmm") -> August | F28: =TEXT(G28, "dddd") -> Thursday | G28: 45141 | H28: CUST027 | I28: Female | J28: 38 | K28: {=_xlfn.IFS(J28<30, "Young Adult", J28<50, "Adult", J28>=50, "Senior")} -> Adult | L28: Beauty | M28: 2 | N28: 25 | O28: =M28*N28 -> 50 | P28: =O28*$S$3 -> 0.75
A29: 28 | B29: =YEAR(G29) -> 2023 | C29: =MONTH(G29) -> 4 | D29: =DAY(G29) -> 23 | E29: =TEXT(G29, "mmmm") -> April | F29: =TEXT(G29, "dddd") -> Sunday | G29: 45039 | H29: CUST028 | I29: Female | J29: 43 | K29: {=_xlfn.IFS(J29<30, "Young Adult", J29<50, "Adult", J29>=50, "Senior")} -> Adult | L29: Beauty | M29: 1 | N29: 500 | O29: =M29*N29 -> 500 | P29: =O29*$S$3 -> 7.5
A30: 29 | B30: =YEAR(G30) -> 2023 | C30: =MONTH(G30) -> 8 | D30: =DAY(G30) -> 18 | E30: =TEXT(G30, "mmmm") -> August | F30: =TEXT(G30, "dddd") -> Friday | G30: 45156 | H30: CUST029 | I30: Female | J30: 42 | K30: {=_xlfn.IFS(J30<30, "Young Adult", J30<50, "Adult", J30>=50, "Senior")} -> Adult | L30: Electronics | M30: 1 | N30: 30 | O30: =M30*N30 -> 30 | P30: =O30*$S$3 -> 0.45
A31: 30 | B31: =YEAR(G31) -> 2023 | C31: =MONTH(G31) -> 10 | D31: =DAY(G31) -> 29 | E31: =TEXT(G31, "mmmm") -> October | F31: =TEXT(G31, "dddd") -> Sunday | G31: 45228 | H31: CUST030 | I31: Female | J31: 39 | K31: {=_xlfn.IFS(J31<30, "Young Adult", J31<50, "Adult", J31>=50, "Senior")} -> Adult | L31: Beauty | M31: 3 | N31: 300 | O31: =M31*N31 -> 900 | P31: =O31*$S$3 -> 13.5
... A44: 43 | B44: =YEAR(G44) -> 2023 | C44: =MONTH(G44) -> 7 | D44: =DAY(G44) -> 14 | E44: =TEXT(G44, "mmmm") -> July | F44: =TEXT(G44, "dddd") -> Friday | G44: 45121 | H44: CUST043 | I44: Female | J44: 48 | K44: {=_xlfn.IFS(J44<30, "Young Adult", J44<50, "Adult", J44>=50, "Senior")} -> Adult | L44: Clothing | M44: 1 | N44: 300 | O44: =M44*N44 -> 300 | P44: =O44*$S$3 -> 4.5
A45: 44 | B45: =YEAR(G45) -> 2023 | C45: =MONTH(G45) -> 2 | D45: =DAY(G45) -> 19 | E45: =TEXT(G45, "mmmm") -> February | F45: =TEXT(G45, "dddd") -> Sunday | G45: 44976 | H45: CUST044 | I45: Female | J45: 22 | K45: {=_xlfn.IFS(J45<30, "Young Adult", J45<50, "Adult", J45>=50, "Senior")} -> Young Adult | L45: Clothing | M45: 1 | N45: 25 | O45: =M45*N45 -> 25 | P45: =O45*$S$3 -> 0.375 | R45: 0
A46: 45 | B46: =YEAR(G46) -> 2023 | C46: =MONTH(G46) -> 7 | D46: =DAY(G46) -> 3 | E46: =TEXT(G46, "mmmm") -> July | F46: =TEXT(G46, "dddd") -> Monday | G46: 45110 | H46: CUST045 | I46: Female | J46: 55 | K46: {=_xlfn.IFS(J46<30, "Young Adult", J46<50, "Adult", J46>=50, "Senior")} -> Senior | L46: Electronics | M46: 1 | N46: 30 | O46: =M46*N46 -> 30 | P46: =O46*$S$3 -> 0.45
A47: 46 | B47: =YEAR(G47) -> 2023 | C47: =MONTH(G47) -> 6 | D47: =DAY(G47) -> 26 | E47: =TEXT(G47, "mmmm") -> June | F47: =TEXT(G47, "dddd") -> Monday | G47: 45103 | H47: CUST046 | I47: Female | J47: 20 | K47: {=_xlfn.IFS(J47<30, "Young Adult", J47<50, "Adult", J47>=50, "Senior")} -> Young Adult | L47: Electronics | M47: 4 | N47: 300 | O47: =M47*N47 -> 1200 | P47: =O47*$S$3 -> 18
A48: 47 | B48: =YEAR(G48) -> 2023 | C48: =MONTH(G48) -> 11 | D48: =DAY(G48) -> 6 | E48: =TEXT(G48, "mmmm") -> November | F48: =TEXT(G48, "dddd") -> Monday | G48: 45236 | H48: CUST047 | I48: Female | J48: 40 | K48: {=_xlfn.IFS(J48<30, "Young Adult", J48<50, "Adult", J48>=50, "Senior")} -> Adult | L48: Beauty | M48: 3 | N48: 500 | O48: =M48*N48 -> 1500 | P48: =O48*$S$3 -> 22.5
A49: 48 | B49: =YEAR(G49) -> 2023 | C49: =MONTH(G49) -> 5 | D49: =DAY(G49) -> 16 | E49: =TEXT(G49, "mmmm") -> May | F49: =TEXT(G49, "dddd") -> Tuesday | G49: 45062 | H49: CUST048 | I49: Male | J49: 54 | K49: {=_xlfn.IFS(J49<30, "Young Adult", J49<50, "Adult", J49>=50, "Senior")} -> Senior | L49: Electronics | M49: 3 | N49: 300 | O49: =M49*N49 -> 900 | P49: =O49*$S$3 -> 13.5
A50: 49 | B50: =YEAR(G50) -> 2023 | C50: =MONTH(G50) -> 1 | D50: =DAY(G50) -> 23 | E50: =TEXT(G50, "mmmm") -> January | F50: =TEXT(G50, "dddd") -> Monday | G50: 44949 | H50: CUST049 | I50: Female | J50: 54 | K50: {=_xlfn.IFS(J50<30, "Young Adult", J50<50, "Adult", J50>=50, "Senior")} -> Senior | L50: Electronics | M50: 2 | N50: 500 | O50: =M50*N50 -> 1000 | P50: =O50*$S$3 -> 15
A51: 50 | B51: =YEAR(G51) -> 2023 | C51: =MONTH(G51) -> 8 | D51: =DAY(G51) -> 24 | E51: =TEXT(G51, "mmmm") -> August | F51: =TEXT(G51, "dddd") -> Thursday | G51: 45162 | H51: CUST050 | I51: Female | J51: 27 | K51: {=_xlfn.IFS(J51<30, "Young Adult", J51<50, "Adult", J51>=50, "Senior")} -> Young Adult | L51: Beauty | M51: 3 | N51: 25 | O51: =M51*N51 -> 75 | P51: =O51*$S$3 -> 1.125
A52: 51 | B52: =YEAR(G52) -> 2023 | C52: =MONTH(G52) -> 10 | D52: =DAY(G52) -> 2 | E52: =TEXT(G52, "mmmm") -> October | F52: =TEXT(G52, "dddd") -> Monday | G52: 45201 | H52: CUST051 | I52: Male | J52: 27 | K52: {=_xlfn.IFS(J52<30, "Young Adult", J52<50, "Adult", J52>=50, "Senior")} -> Young Adult | L52: Beauty | M52: 3 | N52: 25 | O52: =M52*N52 -> 75 | P52: =O52*$S$3 -> 1.125
...

Sheet Transactions
A1: Transaction ID | B1: Total Sales | C1: Product category | D1: Concatenate
A2: 10 | B2: =VLOOKUP(A2, retail_sales_dataset!A1:P1001, 15, FALSE) -> 200 | C2: =VLOOKUP(A2, retail_sales_dataset!A1:P1001, 12, FALSE) -> Clothing | D2: =CONCATENATE(B2, " ",C2) -> 200 Clothing
A3: 15 | B3: =VLOOKUP(A3, retail_sales_dataset!A2:P1002, 15, FALSE) -> 2000 | C3: =VLOOKUP(A3, retail_sales_dataset!A2:P1002, 12, FALSE) -> Electronics | D3: =CONCATENATE(B3, " ",C3) -> 2000 Electronics
A4: 25 | B4: =VLOOKUP(A4, retail_sales_dataset!A3:P1003, 15, FALSE) -> 50 | C4: =VLOOKUP(A4, retail_sales_dataset!A3:P1003, 12, FALSE) -> Beauty | D4: =CONCATENATE(B4, " ",C4) -> 50 Beauty
A5: 30 | B5: =VLOOKUP(A5, retail_sales_dataset!A4:P1004, 15, FALSE) -> 900 | C5: =VLOOKUP(A5, retail_sales_dataset!A4:P1004, 12, FALSE) -> Beauty | D5: =CONCATENATE(B5, " ",C5) -> 900 Beauty
A6: 54 | B6: =VLOOKUP(A6, retail_sales_dataset!A5:P1005, 15, FALSE) -> 1500 | C6: =VLOOKUP(A6, retail_sales_dataset!A5:P1005, 12, FALSE) -> Electronics | D6: =CONCATENATE(B6, " ",C6) -> 1500 Electronics
A7: 55 | B7: =VLOOKUP(A7, retail_sales_dataset!A6:P1006, 15, FALSE) -> 120 | C7: =VLOOKUP(A7, retail_sales_dataset!A6:P1006, 12, FALSE) -> Beauty | D7: =CONCATENATE(B7, " ",C7) -> 120 Beauty
A8: 67 | B8: =VLOOKUP(A8, retail_sales_dataset!A7:P1007, 15, FALSE) -> 1200 | C8: =VLOOKUP(A8, retail_sales_dataset!A7:P1007, 12, FALSE) -> Beauty | D8: =CONCATENATE(B8, " ",C8) -> 1200 Beauty
A9: 89 | B9: =VLOOKUP(A9, retail_sales_dataset!A8:P1008, 15, FALSE) -> 2000 | C9: =VLOOKUP(A9, retail_sales_dataset!A8:P1008, 12, FALSE) -> Electronics | D9: =CONCATENATE(B9, " ",C9) -> 2000 Electronics
A10: 100 | B10: =VLOOKUP(A10, retail_sales_dataset!A9:P1009, 15, FALSE) -> 30 | C10: =VLOOKUP(A10, retail_sales_dataset!A9:P1009, 12, FALSE) -> Electronics | D10: =CONCATENATE(B10, " ",C10) -> 30 Electronics
B12: =COUNT(B2:B10) -> 9

Sheet charts and grahs
A3: Gender | B3: Product Category | C3: Sum of Total Sales
A4: Female | B4: Beauty | C4: 0.16410088
B5: Clothing | C5: 0.17823465
B6: Electronics | C6: 0.16827851
A7: Female Total | C7: 0.51061404
A8: Male | B8: Beauty | C8: 0.150625
B9: Clothing | C9: 0.16294956
B10: Electronics | C10: 0.1758114
A11: Male Total | C11: 0.48938596
A12: Grand Total | C12: 1

Sheet charts and graphs
A3: Product Category | B3: Gender | C3: Generation | D3: Sum of Total Sales
A4: Beauty | B4: Female | C4: Adult | D4: 35170
C5: Senior | D5: 20010
C6: Young Adult | D6: 19650
B7: Female Total | D7: 74830
B8: Male | C8: Adult | D8: 32860
C9: Senior | D9: 14075
C10: Young Adult | D10: 21750
B11: Male Total | D11: 68685
A12: Beauty Total | D12: 143515
A13: Clothing | B13: Female | C13: Adult | D13: 31970
C14: Senior | D14: 25085
C15: Young Adult | D15: 24220
B16: Female Total | D16: 81275
B17: Male | C17: Adult | D17: 30390
C18: Senior | D18: 21985
C19: Young Adult | D19: 21930
B20: Male Total | D20: 74305
A21: Clothing Total | D21: 155580
A22: Electronics | B22: Female | C22: Adult | D22: 30410
C23: Senior | D23: 26670
C24: Young Adult | D24: 19655
B25: Female Total | D25: 76735
B26: Male | C26: Adult | D26: 28890
C27: Senior | D27: 35330
C28: Young Adult | D28: 15950
B29: Male Total | D29: 80170
A30: Electronics Total | D30: 156905
A31: Grand Total | D31: 456000
